Workbook

Sheet rimborso
D1: Spett.le Società
D2: NOME | E2: G8Labs SRL
D3: VIA | E3: Pietro Pisa 74
D4: CAP E CITTA' | E4: 25014, Castenedolo
D5: C.F. e P. IVA: | E5: 4704320987
A7: NOTA SPESE RIMBORSI CHILOMETRICI
A9: IL SIG. Giorgio Giotto
A10: HA EFFETTUATO NEL MESE DI Agosto 2026
A11: MEDIANTE L'USO DELL'AUTOMEZZO DI PROPRIETA'
C13: TARGA | D13: MODELLO | E13: TARIFFA €/KM
A14: AUTOVETTURA | C14: FS760HS | D14: Jeep Compass | E14: 0.5248
A16: I SEGUENTI VIAGGI:
A18: GG | B18: LOCALITA' | D18: OGGETTO | E18: KM | F18: ALTRE SPESE | G18: Note | H18: Tipo trasferta
B19: DA | C19: A
B20: ANDATA E RITORNO
A21: 1 | B21: =IF($H21="","",VLOOKUP($H21,Mapping!$A:$E,2,FALSE())) | C21: =IF($H21="","",VLOOKUP($H21,Mapping!$A:$E,3,FALSE())) | D21: =IF($H21="","",VLOOKUP($H21,Mapping!$A:$E,4,FALSE())) | E21: =IF($H21="","",VLOOKUP($H21,Mapping!$A:$E,5,FALSE()))
A22: 2 | B22: =IF($H22="","",VLOOKUP($H22,Mapping!$A:$E,2,FALSE())) | C22: =IF($H22="","",VLOOKUP($H22,Mapping!$A:$E,3,FALSE())) | D22: =IF($H22="","",VLOOKUP($H22,Mapping!$A:$E,4,FALSE())) | E22: =IF($H22="","",VLOOKUP($H22,Mapping!$A:$E,5,FALSE()))
A23: 3 | B23: =IF($H23="","",VLOOKUP($H23,Mapping!$A:$E,2,FALSE())) | C23: =IF($H23="","",VLOOKUP($H23,Mapping!$A:$E,3,FALSE())) | D23: =IF($H23="","",VLOOKUP($H23,Mapping!$A:$E,4,FALSE())) | E23: =IF($H23="","",VLOOKUP($H23,Mapping!$A:$E,5,FALSE()))
A24: 4 | B24: =IF($H24="","",VLOOKUP($H24,Mapping!$A:$E,2,FALSE())) | C24: =IF($H24="","",VLOOKUP($H24,Mapping!$A:$E,3,FALSE())) | D24: =IF($H24="","",VLOOKUP($H24,Mapping!$A:$E,4,FALSE())) | E24: =IF($H24="","",VLOOKUP($H24,Mapping!$A:$E,5,FALSE()))
A25: 5 | B25: =IF($H25="","",VLOOKUP($H25,Mapping!$A:$E,2,FALSE())) | C25: =IF($H25="","",VLOOKUP($H25,Mapping!$A:$E,3,FALSE())) | D25: =IF($H25="","",VLOOKUP($H25,Mapping!$A:$E,4,FALSE())) | E25: =IF($H25="","",VLOOKUP($H25,Mapping!$A:$E,5,FALSE()))
A26: 6 | B26: =IF($H26="","",VLOOKUP($H26,Mapping!$A:$E,2,FALSE())) -> Via Pisa 74, castenedolo | C26: =IF($H26="","",VLOOKUP($H26,Mapping!$A:$E,3,FALSE())) -> Via Cornalia 19, Milano Sede Alsea | D26: =IF($H26="","",VLOOKUP($H26,Mapping!$A:$E,4,FALSE())) -> Trasferta in sede Alsea | E26: =IF($H26="","",VLOOKUP($H26,Mapping!$A:$E,5,FALSE())) -> 240 | H26: ALSEA
A27: 7 | B27: =IF($H27="","",VLOOKUP($H27,Mapping!$A:$E,2,FALSE())) | C27: =IF($H27="","",VLOOKUP($H27,Mapping!$A:$E,3,FALSE())) | D27: =IF($H27="","",VLOOKUP($H27,Mapping!$A:$E,4,FALSE())) | E27: =IF($H27="","",VLOOKUP($H27,Mapping!$A:$E,5,FALSE()))
A28: 8 | B28: =IF($H28="","",VLOOKUP($H28,Mapping!$A:$E,2,FALSE())) | C28: =IF($H28="","",VLOOKUP($H28,Mapping!$A:$E,3,FALSE())) | D28: =IF($H28="","",VLOOKUP($H28,Mapping!$A:$E,4,FALSE())) | E28: =IF($H28="","",VLOOKUP($H28,Mapping!$A:$E,5,FALSE()))
A29: 9 | B29: =IF($H29="","",VLOOKUP($H29,Mapping!$A:$E,2,FALSE())) | C29: =IF($H29="","",VLOOKUP($H29,Mapping!$A:$E,3,FALSE())) | D29: =IF($H29="","",VLOOKUP($H29,Mapping!$A:$E,4,FALSE())) | E29: =IF($H29="","",VLOOKUP($H29,Mapping!$A:$E,5,FALSE()))
A30: 10 | B30: =IF($H30="","",VLOOKUP($H30,Mapping!$A:$E,2,FALSE())) | C30: =IF($H30="","",VLOOKUP($H30,Mapping!$A:$E,3,FALSE())) | D30: =IF($H30="","",VLOOKUP($H30,Mapping!$A:$E,4,FALSE())) | E30: =IF($H30="","",VLOOKUP($H30,Mapping!$A:$E,5,FALSE()))
A31: 11 | B31: =IF($H31="","",VLOOKUP($H31,Mapping!$A:$E,2,FALSE())) | C31: =IF($H31="","",VLOOKUP($H31,Mapping!$A:$E,3,FALSE())) | D31: =IF($H31="","",VLOOKUP($H31,Mapping!$A:$E,4,FALSE())) | E31: =IF($H31="","",VLOOKUP($H31,Mapping!$A:$E,5,FALSE()))
A32: 12 | B32: =IF($H32="","",VLOOKUP($H32,Mapping!$A:$E,2,FALSE())) | C32: =IF($H32="","",VLOOKUP($H32,Mapping!$A:$E,3,FALSE())) | D32: =IF($H32="","",VLOOKUP($H32,Mapping!$A:$E,4,FALSE())) | E32: =IF($H32="","",VLOOKUP($H32,Mapping!$A:$E,5,FALSE()))
A33: 13 | B33: =IF($H33="","",VLOOKUP($H33,Mapping!$A:$E,2,FALSE())) | C33: =IF($H33="","",VLOOKUP($H33,Mapping!$A:$E,3,FALSE())) | D33: =IF($H33="","",VLOOKUP($H33,Mapping!$A:$E,4,FALSE())) | E33: =IF($H33="","",VLOOKUP($H33,Mapping!$A:$E,5,FALSE()))
A34: 14 | B34: =IF($H34="","",VLOOKUP($H34,Mapping!$A:$E,2,FALSE())) | C34: =IF($H34="","",VLOOKUP($H34,Mapping!$A:$E,3,FALSE())) | D34: =IF($H34="","",VLOOKUP($H34,Mapping!$A:$E,4,FALSE())) | E34: =IF($H34="","",VLOOKUP($H34,Mapping!$A:$E,5,FALSE()))
A35: 15 | B35: =IF($H35="","",VLOOKUP($H35,Mapping!$A:$E,2,FALSE())) | C35: =IF($H35="","",VLOOKUP($H35,Mapping!$A:$E,3,FALSE())) | D35: =IF($H35="","",VLOOKUP($H35,Mapping!$A:$E,4,FALSE())) | E35: =IF($H35="","",VLOOKUP($H35,Mapping!$A:$E,5,FALSE()))
A36: 16 | B36: =IF($H36="","",VLOOKUP($H36,Mapping!$A:$E,2,FALSE())) | C36: =IF($H36="","",VLOOKUP($H36,Mapping!$A:$E,3,FALSE())) | D36: =IF($H36="","",VLOOKUP($H36,Mapping!$A:$E,4,FALSE())) | E36: =IF($H36="","",VLOOKUP($H36,Mapping!$A:$E,5,FALSE()))
A37: 17 | B37: =IF($H37="","",VLOOKUP($H37,Mapping!$A:$E,2,FALSE())) | C37: =IF($H37="","",VLOOKUP($H37,Mapping!$A:$E,3,FALSE())) | D37: =IF($H37="","",VLOOKUP($H37,Mapping!$A:$E,4,FALSE())) | E37: =IF($H37="","",VLOOKUP($H37,Mapping!$A:$E,5,FALSE()))
A38: 18 | B38: =IF($H38="","",VLOOKUP($H38,Mapping!$A:$E,2,FALSE())) | C38: =IF($H38="","",VLOOKUP($H38,Mapping!$A:$E,3,FALSE())) | D38: =IF($H38="","",VLOOKUP($H38,Mapping!$A:$E,4,FALSE())) | E38: =IF($H38="","",VLOOKUP($H38,Mapping!$A:$E,5,FALSE()))
... A47: 27 | B47: =IF($H47="","",VLOOKUP($H47,Mapping!$A:$E,2,FALSE())) | C47: =IF($H47="","",VLOOKUP($H47,Mapping!$A:$E,3,FALSE())) | D47: =IF($H47="","",VLOOKUP($H47,Mapping!$A:$E,4,FALSE())) | E47: =IF($H47="","",VLOOKUP($H47,Mapping!$A:$E,5,FALSE()))
A48: 28 | B48: =IF($H48="","",VLOOKUP($H48,Mapping!$A:$E,2,FALSE())) -> Via Pisa 74, castenedolo | C48: =IF($H48="","",VLOOKUP($H48,Mapping!$A:$E,3,FALSE())) -> Via Cornalia 19, Milano Sede Fedespedi | D48: =IF($H48="","",VLOOKUP($H48,Mapping!$A:$E,4,FALSE())) -> Trasferta in sede Fedespedi | E48: =IF($H48="","",VLOOKUP($H48,Mapping!$A:$E,5,FALSE())) -> 240 | H48: FEDESPEDI
A49: 29 | B49: =IF($H49="","",VLOOKUP($H49,Mapping!$A:$E,2,FALSE())) | C49: =IF($H49="","",VLOOKUP($H49,Mapping!$A:$E,3,FALSE())) | D49: =IF($H49="","",VLOOKUP($H49,Mapping!$A:$E,4,FALSE())) | E49: =IF($H49="","",VLOOKUP($H49,Mapping!$A:$E,5,FALSE()))
A50: 30 | B50: =IF($H50="","",VLOOKUP($H50,Mapping!$A:$E,2,FALSE())) | C50: =IF($H50="","",VLOOKUP($H50,Mapping!$A:$E,3,FALSE())) | D50: =IF($H50="","",VLOOKUP($H50,Mapping!$A:$E,4,FALSE())) | E50: =IF($H50="","",VLOOKUP($H50,Mapping!$A:$E,5,FALSE()))
A51: 31 | B51: =IF($H51="","",VLOOKUP($H51,Mapping!$A:$E,2,FALSE())) | C51: =IF($H51="","",VLOOKUP($H51,Mapping!$A:$E,3,FALSE())) | D51: =IF($H51="","",VLOOKUP($H51,Mapping!$A:$E,4,FALSE())) | E51: =IF($H51="","",VLOOKUP($H51,Mapping!$A:$E,5,FALSE()))
E52: =SUM(E21:E51) -> 480 | F52: =SUM(F21:F51) -> 0
C54: INDENNITA' KM | E54: =E52*E14 -> 251.904
...

Sheet Mapping
A1: Tipo trasferta | B1: Da | C1: A | D1: Oggetto | E1: KM
A2: ALSEA | B2: Via Pisa 74, castenedolo | C2: Via Cornalia 19, Milano Sede Alsea | D2: Trasferta in sede Alsea | E2: 240
A3: FIORAVANTI | B3: Via Pisa 74, castenedolo | C3: Via siglindi, Corana (PV) | D3: Trasferta Fioravanti | E3: 350
A4: FEDESPEDI | B4: Via Pisa 74, castenedolo | C4: Via Cornalia 19, Milano Sede Fedespedi | D4: Trasferta in sede Fedespedi | E4: 240
A5: FIORAVANTI AGNADELLO | B5: Via Pisa 74, castenedolo | C5: Via siglindi, Corana (PV) | D5: trasferta a Corana per fioravanti passando da agnadello | E5: =200+200 -> 400
A9: km fine | B9: 161
